Workbook

Sheet Compliance Matrix
A1: OSS911 (MOI) RFP – VENDOR COMPLIANCE & PRICING MATRIX
A2: Vendor / Bidder name: | B2: AI Innovation Solutions Co. (AIIS) | F2: Date: | G2: Scope of this response: Part 1, Clause 1.6.2 — OSS911 Solution Business Intelligence, Database Repository, Dashboards and Reports. Pricing not included in this revision.
A3: S/N | B3: Clause No. | C3: Part | D3: Section | E3: Sub-Section | F3: Requirement Description (as per RFP) | G3: Compliance (C / PC / NC / N/A) | H3: Proposed OEM / Vendor | I3: Proposed Product / Model / Part No. | J3: Qty | K3: Unit Price (SAR) | L3: Total Price (SAR) | M3: Lead Time (Weeks) | N3: Proposal Reference (Doc / Page) | O3: Vendor Remarks / Deviations
A4: 1 | B4: 1.2.1.1 | C4: Part 1 – General & Programme | D4: 1.2 THE OSS911 PROJECT | E4: 1.2.1 SYNOPSIS OF REQUIREMENTS | F4: The BIDDER shall note that this RFP is non-prescriptive regarding vendor and vendor technologies, and is vendor agnostic. | L4: =IF(OR(J4="",K4=""),"",J4*K4)
A5: 2 | B5: 1.2.1.2 | C5: Part 1 – General & Programme | D5: 1.2 THE OSS911 PROJECT | E5: 1.2.1 SYNOPSIS OF REQUIREMENTS | F5: The BIDDER shall propose their solutions that help them to deliver all the requirements of the RFP while complying to industry best practices. | L5: =IF(OR(J5="",K5=""),"",J5*K5)
A6: 3 | B6: 1.2.1.3 | C6: Part 1 – General & Programme | D6: 1.2 THE OSS911 PROJECT | E6: 1.2.1 SYNOPSIS OF REQUIREMENTS | F6: The BIDDER shall note that the design and construction of any of the OSS911 facilities is not part of this RFP. | L6: =IF(OR(J6="",K6=""),"",J6*K6)
A7: 4 | B7: 1.2.1.4 | C7: Part 1 – General & Programme | D7: 1.2 THE OSS911 PROJECT | E7: 1.2.1 SYNOPSIS OF REQUIREMENTS | F7: The BIDDER shall note that each OSS911 Center will be linked to all other OSS911 Centers via an-MOI provided wide area network backbone dark fiber (MiFON). | L7: =IF(OR(J7="",K7=""),"",J7*K7)
A8: 5 | B8: 1.2.1.5 | C8: Part 1 – General & Programme | D8: 1.2 THE OSS911 PROJECT | E8: 1.2.1 SYNOPSIS OF REQUIREMENTS | F8: The BIDDER shall calculate the bandwidth of the network connectivity required with other OSS911 centers in order to meet this RFP requirements for its concept of operations, functionality, performance and availability, and shall include those in the network edge devices that they will be using for connectivity to the MiFON backbone for various OSS911 solution needs. | L8: =IF(OR(J8="",K8=""),"",J8*K8)
A9: 6 | B9: 1.2.1.6 | C9: Part 1 – General & Programme | D9: 1.2 THE OSS911 PROJECT | E9: 1.2.1 SYNOPSIS OF REQUIREMENTS | F9: The BIDDER shall note that the MOI have the right to involve their technical specialists during the project contract duration to work closely with the contractor and the subcontractor technical teams for continual knowhow and knowledge absorption. | L9: =IF(OR(J9="",K9=""),"",J9*K9)
A10: 7 | B10: 1.2.1.7 | C10: Part 1 – General & Programme | D10: 1.2 THE OSS911 PROJECT | E10: 1.2.1 SYNOPSIS OF REQUIREMENTS | F10: The BIDDER proposal shall follow the format and bid structure and content instructions that have been provided in the Arabic section of this RFP. | L10: =IF(OR(J10="",K10=""),"",J10*K10)
A11: 8 | B11: 1.2.1.8 | C11: Part 1 – General & Programme | D11: 1.2 THE OSS911 PROJECT | E11: 1.2.1 SYNOPSIS OF REQUIREMENTS | F11: The BIDDER shall provide a complete and integrated high-level design of their OSS911 system solution in their proposal along with a high-level narrative describing each functional elements of the design along with example use-cases of the function and the workflows. | L11: =IF(OR(J11="",K11=""),"",J11*K11)
A12: 9 | B12: 1.2.1.9 | C12: Part 1 – General & Programme | D12: 1.2 THE OSS911 PROJECT | E12: 1.2.1 SYNOPSIS OF REQUIREMENTS | F12: The BIDDER shall ratify any and all of their assumptions as part of the bid Q&A process. | L12: =IF(OR(J12="",K12=""),"",J12*K12)
A13: 10 | B13: 1.2.1.10 | C13: Part 1 – General & Programme | D13: 1.2 THE OSS911 PROJECT | E13: 1.2.1 SYNOPSIS OF REQUIREMENTS | F13: The BIDDER shall note that when BIDDER confirms compliance to any and all clauses within this RFP, it implies that the BIDDER is fully compliant with the MOI requirements without any conditions, assumptions, constraints, exclusions and exceptions – stated and/or implied. | L13: =IF(OR(J13="",K13=""),"",J13*K13)
A14: 11 | B14: 1.2.1.11 | C14: Part 1 – General & Programme | D14: 1.2 THE OSS911 PROJECT | E14: 1.2.1 SYNOPSIS OF REQUIREMENTS | F14: The BIDDER shall note that further to the confirmation of their compliance to any clause, any notes within in their proposal that imply an assumption or condition or constraint or exclusion or exception implicitly or explicitly, shall not be considered as part of the BIDDER proposal. Further, such conditional content in the proposal will negatively impact the evaluation of the proposal compliance with the MOI requirements. | L14: =IF(OR(J14="",K14=""),"",J14*K14)
A15: 12 | B15: 1.2.1.12 | C15: Part 1 – General & Programme | D15: 1.2 THE OSS911 PROJECT | E15: 1.2.1 SYNOPSIS OF REQUIREMENTS | F15: The BIDDER response shall include the planning, design, supply, installation, configuration, testing, training, commissioning, management and assurance of all components. | L15: =IF(OR(J15="",K15=""),"",J15*K15)
... A395: 392 | B395: 1.6.1.55.11 | C395: Part 1 – General & Programme | D395: 1.6 SYSTEMS DEVELOPMENT, INTEGRATION AND TESTING | E395: 1.6.1 REQUIREMENTS FOR A FULLY INTEGRATED OSS911 SOLUTION | F395: Radio ID | L395: =IF(OR(J395="",K395=""),"",J395*K395)
A396: 393 | B396: 1.6.2.1 | C396: Part 1 – General & Programme | D396: 1.6 SYSTEMS DEVELOPMENT, INTEGRATION AND TESTING | E396: 1.6.2 OSS911 SOLUTION BUSINESS INTELLIGENCE, DATABASE REPOSITORY, DASHBOARDS AND REPORTS | F396: The CONTRACTOR shall migrate existing operational data from existing datastores for Makkah 911 center into the single highly available structured relational database for the OSS911 solution. | G396: C | H396: AI Innovation Solutions Co. (AIIS) | I396: Nexora-BI | L396: =IF(OR(J396="",K396=""),"",J396*K396) | N396: Nexora-BI §5; §9 Phase 04 | O396: Historical data of the existing Makkah 911 centre is loaded once from the archive database into the central repository, followed by complete record-level reconciliation.
A397: 394 | B397: 1.6.2.2 | C397: Part 1 – General & Programme | D397: 1.6 SYSTEMS DEVELOPMENT, INTEGRATION AND TESTING | E397: 1.6.2 OSS911 SOLUTION BUSINESS INTELLIGENCE, DATABASE REPOSITORY, DASHBOARDS AND REPORTS | F397: The CONTRACTOR shall implement all the requirements as below on the single highly available structured relational database for the OSS911 solution. | G397: C | H397: AI Innovation Solutions Co. (AIIS) | I397: Nexora-BI | L397: =IF(OR(J397="",K397=""),"",J397*K397) | N397: Nexora-BI §3; §3.1; §8 | O397: Delivered by Nexora-BI within the business intelligence, data warehouse, dashboard and reporting scope.
A398: 395 | B398: 1.6.2.3 | C398: Part 1 – General & Programme | D398: 1.6 SYSTEMS DEVELOPMENT, INTEGRATION AND TESTING | E398: 1.6.2 OSS911 SOLUTION BUSINESS INTELLIGENCE, DATABASE REPOSITORY, DASHBOARDS AND REPORTS | F398: The CONTRACTOR shall implement a highly available smart and AI- powered central structured information database solution that combines in a relational database the data from the different subsystems of the OSS911 solution and from any other relational databases identified by the MOI during the design stage. | G398: C | H398: AI Innovation Solutions Co. (AIIS) | I398: Nexora-BI | L398: =IF(OR(J398="",K398=""),"",J398*K398) | N398: Nexora-BI §3; §3.1; §8 | O398: Highly available PostgreSQL repository consolidating the OSS911 subsystem data in one conformed relational model. The repository tier is intelligence-assisted: index and query-plan advisory, workload-aware optimisation, data anomaly detection and capacity trend forecasting.
A399: 396 | B399: 1.6.2.4 | C399: Part 1 – General & Programme | D399: 1.6 SYSTEMS DEVELOPMENT, INTEGRATION AND TESTING | E399: 1.6.2 OSS911 SOLUTION BUSINESS INTELLIGENCE, DATABASE REPOSITORY, DASHBOARDS AND REPORTS | F399: The CONTRACTOR shall deliver this highly available central structured database repository solution for all OSS911 systems covering: | G399: C | H399: AI Innovation Solutions Co. (AIIS) | I399: Nexora-BI | L399: =IF(OR(J399="",K399=""),"",J399*K399) | N399: Nexora-BI §3; §3.1; §8 | O399: Delivered by Nexora-BI within the business intelligence, data warehouse, dashboard and reporting scope.
A400: 397 | B400: 1.6.2.4.1 | C400: Part 1 – General & Programme | D400: 1.6 SYSTEMS DEVELOPMENT, INTEGRATION AND TESTING | E400: 1.6.2 OSS911 SOLUTION BUSINESS INTELLIGENCE, DATABASE REPOSITORY, DASHBOARDS AND REPORTS | F400: Live data | G400: C | H400: AI Innovation Solutions Co. (AIIS) | I400: Nexora-BI | L400: =IF(OR(J400="",K400=""),"",J400*K400) | N400: Nexora-BI §3; §3.1; §8 | O400: Delivered by Nexora-BI within the business intelligence, data warehouse, dashboard and reporting scope.
A401: 398 | B401: 1.6.2.4.2 | C401: Part 1 – General & Programme | D401: 1.6 SYSTEMS DEVELOPMENT, INTEGRATION AND TESTING | E401: 1.6.2 OSS911 SOLUTION BUSINESS INTELLIGENCE, DATABASE REPOSITORY, DASHBOARDS AND REPORTS | F401: Historical data (any data that is older than the current day) | G401: C | H401: AI Innovation Solutions Co. (AIIS) | I401: Nexora-BI | L401: =IF(OR(J401="",K401=""),"",J401*K401) | N401: Nexora-BI §3; §3.1; §8 | O401: Delivered by Nexora-BI within the business intelligence, data warehouse, dashboard and reporting scope.
A402: 399 | B402: 1.6.2.5 | C402: Part 1 – General & Programme | D402: 1.6 SYSTEMS DEVELOPMENT, INTEGRATION AND TESTING | E402: 1.6.2 OSS911 SOLUTION BUSINESS INTELLIGENCE, DATABASE REPOSITORY, DASHBOARDS AND REPORTS | F402: The CONTRACTOR shall consider for the central OSS911 database repository the expected amount of data related to the incident and different data from different systems and shall apply the best practices related to the database design, implementation, administration, and maintenance this shall include but not limited to (Indexing, Portioning, Indexed Views, Optimized queries, Period routine database checks and reports.). | G402: C | H402: AI Innovation Solutions Co. (AIIS) | I402: Nexora-BI | L402: =IF(OR(J402="",K402=""),"",J402*K402) | N402: Nexora-BI §3; §3.1; §8 | O402: Indexing, partitioning, indexed views, query optimisation and scheduled routine database checks with periodic health reports.
A403: 400 | B403: 1.6.2.6 | C403: Part 1 – General & Programme | D403: 1.6 SYSTEMS DEVELOPMENT, INTEGRATION AND TESTING | E403: 1.6.2 OSS911 SOLUTION BUSINESS INTELLIGENCE, DATABASE REPOSITORY, DASHBOARDS AND REPORTS | F403: The CONTRACTOR shall consider the expected database expansion and provide capacity planning for this database. | G403: C | H403: AI Innovation Solutions Co. (AIIS) | I403: Nexora-BI | L403: =IF(OR(J403="",K403=""),"",J403*K403) | N403: Nexora-BI §3; §3.1; §8 | O403: Delivered by Nexora-BI within the business intelligence, data warehouse, dashboard and reporting scope.
A404: 401 | B404: 1.6.2.7 | C404: Part 1 – General & Programme | D404: 1.6 SYSTEMS DEVELOPMENT, INTEGRATION AND TESTING | E404: 1.6.2 OSS911 SOLUTION BUSINESS INTELLIGENCE, DATABASE REPOSITORY, DASHBOARDS AND REPORTS | F404: All OSS911 contractor supplied databases and any information received from the OSS911 connections to the legacy databases connected to OSS911 shall be searchable against a configurable set of selection parameters and criteria which shall be displayed to operators for immediate recovery. | G404: C | H404: AI Innovation Solutions Co. (AIIS) | I404: Nexora-BI | L404: =IF(OR(J404="",K404=""),"",J404*K404) | N404: Nexora-BI §3; §3.1; §8 | O404: Nexora-BI is the business intelligence, data warehouse, dashboard and reporting component of the OSS911 solution. This response addresses that component; data produced by the CAD/IRMS, telephony and other subsystems is consumed through the interfaces of Nexora-BI §5 and §10.1. Searchable against a configurable set of selection parameters, presented to authorised users through the Nexora-BI browser interface for immediate recovery.
A405: 402 | B405: 1.6.2.8 | C405: Part 1 – General & Programme | D405: 1.6 SYSTEMS DEVELOPMENT, INTEGRATION AND TESTING | E405: 1.6.2 OSS911 SOLUTION BUSINESS INTELLIGENCE, DATABASE REPOSITORY, DASHBOARDS AND REPORTS | F405: The CONTRACTOR implementation of the OSS911 solution shall enable an authorized user to be able to query and generate smart and AI-powered reports, both on a regular and ad-hoc basis, based on a set of parameters, which may include, or exclude, incidents from more than one agency, and which may include or exclude, data relating to one or more subsystems of the OSS911 solution. | G405: C | H405: AI Innovation Solutions Co. (AIIS) | I405: Nexora-BI | L405: =IF(OR(J405="",K405=""),"",J405*K405) | N405: Nexora-BI §6; §6.1 | O405: Delivered by Nexora-BI within the business intelligence, data warehouse, dashboard and reporting scope.
A406: 403 | B406: 1.6.2.9 | C406: Part 1 – General & Programme | D406: 1.6 SYSTEMS DEVELOPMENT, INTEGRATION AND TESTING | E406: 1.6.2 OSS911 SOLUTION BUSINESS INTELLIGENCE, DATABASE REPOSITORY, DASHBOARDS AND REPORTS | F406: The CONTRACTOR shall conduct workshops with the MOI for the CONTRACTOR to define the parameters to be queried, along with the search criteria, the views enabling the queries, the expected output and the visual and printed layout of the output. | G406: C | H406: AI Innovation Solutions Co. (AIIS) | I406: Nexora-BI | L406: =IF(OR(J406="",K406=""),"",J406*K406) | N406: Nexora-BI §6; §6.1 | O406: Delivered by Nexora-BI within the business intelligence, data warehouse, dashboard and reporting scope.
A407: 404 | B407: 1.6.2.10 | C407: Part 1 – General & Programme | D407: 1.6 SYSTEMS DEVELOPMENT, INTEGRATION AND TESTING | E407: 1.6.2 OSS911 SOLUTION BUSINESS INTELLIGENCE, DATABASE REPOSITORY, DASHBOARDS AND REPORTS | F407: The CONTRACTOR shall implement the defined queries, views and reports from the different OSS911 databases. | G407: C | H407: AI Innovation Solutions Co. (AIIS) | I407: Nexora-BI | L407: =IF(OR(J407="",K407=""),"",J407*K407) | N407: Nexora-BI §6; §6.1 | O407: Delivered by Nexora-BI within the business intelligence, data warehouse, dashboard and reporting scope.
... A447: 444 | B447: 1.6.2.33 | C447: Part 1 – General & Programme | D447: 1.6 SYSTEMS DEVELOPMENT, INTEGRATION AND TESTING | E447: 1.6.2 OSS911 SOLUTION BUSINESS INTELLIGENCE, DATABASE REPOSITORY, DASHBOARDS AND REPORTS | F447: When a given OSS911 center is working as a failover center, the CONTRACTOR solution for business intelligence and dashboards shall provide a single unified dashboard for the OSS911 centers that are being served, while maintaining identification and display of the parameters and statistics by province individually. | G447: C | H447: AI Innovation Solutions Co. (AIIS) | I447: Nexora-BI | L447: =IF(OR(J447="",K447=""),"",J447*K447) | N447: Nexora-BI §8 | O447: The Nexora-BI business intelligence and dashboard architecture provides a single unified dashboard across the OSS911 centres served, with parameters and statistics identified and displayed by province individually.
A448: 445 | B448: 1.6.3.1 | C448: Part 1 – General & Programme | D448: 1.6 SYSTEMS DEVELOPMENT, INTEGRATION AND TESTING | E448: 1.6.3 INTEGRATION WITH RESOURCE INFORMATION SYSTEMS | F448: The CONTRACTOR shall deliver an OSS911 solution that shall be integrated through web services with the resources data available from the sources identified by the MOI and that is stored in the centralized database repository for the OSS911 solution. | L448: =IF(OR(J448="",K448=""),"",J448*K448)
A449: 446 | B449: 1.6.3.2 | C449: Part 1 – General & Programme | D449: 1.6 SYSTEMS DEVELOPMENT, INTEGRATION AND TESTING | E449: 1.6.3 INTEGRATION WITH RESOURCE INFORMATION SYSTEMS | F449: The CONTRACTOR shall deliver integration of the OSS911 solution with different resource information and data systems in the form of an integrated relational database-based information and a central data repository available to all OSS911 solution. | L449: =IF(OR(J449="",K449=""),"",J449*K449)
A450: 447 | B450: 1.6.3.3 | C450: Part 1 – General & Programme | D450: 1.6 SYSTEMS DEVELOPMENT, INTEGRATION AND TESTING | E450: 1.6.3 INTEGRATION WITH RESOURCE INFORMATION SYSTEMS | F450: The CONTRACTOR shall capture, populate, maintain and administer within OSS911 systems integrated relational database the data and information related to the different third parties involved. | L450: =IF(OR(J450="",K450=""),"",J450*K450)
A451: 448 | B451: 1.6.3.4 | C451: Part 1 – General & Programme | D451: 1.6 SYSTEMS DEVELOPMENT, INTEGRATION AND TESTING | E451: 1.6.3 INTEGRATION WITH RESOURCE INFORMATION SYSTEMS | F451: The CONTRACTOR delivered information repository shall allow all management and maintenance operations with the integrated relational database for authorized users including create, update, modify, query, insert, view, report, delete, print, export etc. along with the required tools for achieving these operations. | L451: =IF(OR(J451="",K451=""),"",J451*K451)
A452: 449 | B452: 1.6.3.5 | C452: Part 1 – General & Programme | D452: 1.6 SYSTEMS DEVELOPMENT, INTEGRATION AND TESTING | E452: 1.6.3 INTEGRATION WITH RESOURCE INFORMATION SYSTEMS | F452: The CONTRACTOR shall deliver this integration such that it allows OSS911 systems to interface with, consume services from, and exchange data with other external systems including but not limited to: | L452: =IF(OR(J452="",K452=""),"",J452*K452)
A453: 450 | B453: 1.6.3.5.1 | C453: Part 1 – General & Programme | D453: 1.6 SYSTEMS DEVELOPMENT, INTEGRATION AND TESTING | E453: 1.6.3 INTEGRATION WITH RESOURCE INFORMATION SYSTEMS | F453: Other AI-enabled tools and information systems | L453: =IF(OR(J453="",K453=""),"",J453*K453)
A454: 451 | B454: 1.6.3.5.2 | C454: Part 1 – General & Programme | D454: 1.6 SYSTEMS DEVELOPMENT, INTEGRATION AND TESTING | E454: 1.6.3 INTEGRATION WITH RESOURCE INFORMATION SYSTEMS | F454: Other communication systems utilizing SIP protocol and SIP protocol extensions | L454: =IF(OR(J454="",K454=""),"",J454*K454)
A455: 452 | B455: 1.6.3.5.3 | C455: Part 1 – General & Programme | D455: 1.6 SYSTEMS DEVELOPMENT, INTEGRATION AND TESTING | E455: 1.6.3 INTEGRATION WITH RESOURCE INFORMATION SYSTEMS | F455: Other computer aided dispatch systems | L455: =IF(OR(J455="",K455=""),"",J455*K455)
A456: 453 | B456: 1.6.3.5.4 | C456: Part 1 – General & Programme | D456: 1.6 SYSTEMS DEVELOPMENT, INTEGRATION AND TESTING | E456: 1.6.3 INTEGRATION WITH RESOURCE INFORMATION SYSTEMS | F456: Other Geographical Information Systems (GIS) | L456: =IF(OR(J456="",K456=""),"",J456*K456)
A457: 454 | B457: 1.6.3.5.5 | C457: Part 1 – General & Programme | D457: 1.6 SYSTEMS DEVELOPMENT, INTEGRATION AND TESTING | E457: 1.6.3 INTEGRATION WITH RESOURCE INFORMATION SYSTEMS | F457: Other video management systems | L457: =IF(OR(J457="",K457=""),"",J457*K457)
A458: 455 | B458: 1.6.3.5.6 | C458: Part 1 – General & Programme | D458: 1.6 SYSTEMS DEVELOPMENT, INTEGRATION AND TESTING | E458: 1.6.3 INTEGRATION WITH RESOURCE INFORMATION SYSTEMS | F458: Other hearing-impaired systems with video call capability | L458: =IF(OR(J458="",K458=""),"",J458*K458)
...

Sheet Summary
A1: COMPLIANCE & PRICING SUMMARY BY SECTION
A3: Section | B3: Requirements | C3: C | D3: PC | E3: NC | F3: N/A | G3: Not Answered | H3: % Fully Compliant | I3: Section Price (SAR)
A4: 1.2 THE OSS911 PROJECT | B4: =COUNTIF('Compliance Matrix'!$D$4:$D$2256,$A4) | C4: =COUNTIFS('Compliance Matrix'!$D$4:$D$2256,$A4,'Compliance Matrix'!$G$4:$G$2256,"C") | D4: =COUNTIFS('Compliance Matrix'!$D$4:$D$2256,$A4,'Compliance Matrix'!$G$4:$G$2256,"PC") | E4: =COUNTIFS('Compliance Matrix'!$D$4:$D$2256,$A4,'Compliance Matrix'!$G$4:$G$2256,"NC") | F4: =COUNTIFS('Compliance Matrix'!$D$4:$D$2256,$A4,'Compliance Matrix'!$G$4:$G$2256,"N/A") | G4: =B4-SUM(C4:F4) | H4: =IF($B4=0,0,C4/$B4) | I4: =SUMIF('Compliance Matrix'!$D$4:$D$2256,$A4,'Compliance Matrix'!$L$4:$L$2256)
A5: 1.3 CONCEPT OF OPERATIONS (CONOPS) | B5: =COUNTIF('Compliance Matrix'!$D$4:$D$2256,$A5) | C5: =COUNTIFS('Compliance Matrix'!$D$4:$D$2256,$A5,'Compliance Matrix'!$G$4:$G$2256,"C") | D5: =COUNTIFS('Compliance Matrix'!$D$4:$D$2256,$A5,'Compliance Matrix'!$G$4:$G$2256,"PC") | E5: =COUNTIFS('Compliance Matrix'!$D$4:$D$2256,$A5,'Compliance Matrix'!$G$4:$G$2256,"NC") | F5: =COUNTIFS('Compliance Matrix'!$D$4:$D$2256,$A5,'Compliance Matrix'!$G$4:$G$2256,"N/A") | G5: =B5-SUM(C5:F5) | H5: =IF($B5=0,0,C5/$B5) | I5: =SUMIF('Compliance Matrix'!$D$4:$D$2256,$A5,'Compliance Matrix'!$L$4:$L$2256)
A6: 1.4 PROJECT MANAGEMENT | B6: =COUNTIF('Compliance Matrix'!$D$4:$D$2256,$A6) | C6: =COUNTIFS('Compliance Matrix'!$D$4:$D$2256,$A6,'Compliance Matrix'!$G$4:$G$2256,"C") | D6: =COUNTIFS('Compliance Matrix'!$D$4:$D$2256,$A6,'Compliance Matrix'!$G$4:$G$2256,"PC") | E6: =COUNTIFS('Compliance Matrix'!$D$4:$D$2256,$A6,'Compliance Matrix'!$G$4:$G$2256,"NC") | F6: =COUNTIFS('Compliance Matrix'!$D$4:$D$2256,$A6,'Compliance Matrix'!$G$4:$G$2256,"N/A") | G6: =B6-SUM(C6:F6) | H6: =IF($B6=0,0,C6/$B6) | I6: =SUMIF('Compliance Matrix'!$D$4:$D$2256,$A6,'Compliance Matrix'!$L$4:$L$2256)
A7: 1.5 TECHNICAL AND OPERATIONS SERVICE MANAGEMENT AND SUPPORT (TOSMS) | B7: =COUNTIF('Compliance Matrix'!$D$4:$D$2256,$A7) | C7: =COUNTIFS('Compliance Matrix'!$D$4:$D$2256,$A7,'Compliance Matrix'!$G$4:$G$2256,"C") | D7: =COUNTIFS('Compliance Matrix'!$D$4:$D$2256,$A7,'Compliance Matrix'!$G$4:$G$2256,"PC") | E7: =COUNTIFS('Compliance Matrix'!$D$4:$D$2256,$A7,'Compliance Matrix'!$G$4:$G$2256,"NC") | F7: =COUNTIFS('Compliance Matrix'!$D$4:$D$2256,$A7,'Compliance Matrix'!$G$4:$G$2256,"N/A") | G7: =B7-SUM(C7:F7) | H7: =IF($B7=0,0,C7/$B7) | I7: =SUMIF('Compliance Matrix'!$D$4:$D$2256,$A7,'Compliance Matrix'!$L$4:$L$2256)
A8: 1.6 SYSTEMS DEVELOPMENT, INTEGRATION AND TESTING | B8: =COUNTIF('Compliance Matrix'!$D$4:$D$2256,$A8) | C8: =COUNTIFS('Compliance Matrix'!$D$4:$D$2256,$A8,'Compliance Matrix'!$G$4:$G$2256,"C") | D8: =COUNTIFS('Compliance Matrix'!$D$4:$D$2256,$A8,'Compliance Matrix'!$G$4:$G$2256,"PC") | E8: =COUNTIFS('Compliance Matrix'!$D$4:$D$2256,$A8,'Compliance Matrix'!$G$4:$G$2256,"NC") | F8: =COUNTIFS('Compliance Matrix'!$D$4:$D$2256,$A8,'Compliance Matrix'!$G$4:$G$2256,"N/A") | G8: =B8-SUM(C8:F8) | H8: =IF($B8=0,0,C8/$B8) | I8: =SUMIF('Compliance Matrix'!$D$4:$D$2256,$A8,'Compliance Matrix'!$L$4:$L$2256)
A9: 1.7 TRAINING | B9: =COUNTIF('Compliance Matrix'!$D$4:$D$2256,$A9) | C9: =COUNTIFS('Compliance Matrix'!$D$4:$D$2256,$A9,'Compliance Matrix'!$G$4:$G$2256,"C") | D9: =COUNTIFS('Compliance Matrix'!$D$4:$D$2256,$A9,'Compliance Matrix'!$G$4:$G$2256,"PC") | E9: =COUNTIFS('Compliance Matrix'!$D$4:$D$2256,$A9,'Compliance Matrix'!$G$4:$G$2256,"NC") | F9: =COUNTIFS('Compliance Matrix'!$D$4:$D$2256,$A9,'Compliance Matrix'!$G$4:$G$2256,"N/A") | G9: =B9-SUM(C9:F9) | H9: =IF($B9=0,0,C9/$B9) | I9: =SUMIF('Compliance Matrix'!$D$4:$D$2256,$A9,'Compliance Matrix'!$L$4:$L$2256)
A10: 2.1 Geographical Information System (GIS) | B10: =COUNTIF('Compliance Matrix'!$D$4:$D$2256,$A10) | C10: =COUNTIFS('Compliance Matrix'!$D$4:$D$2256,$A10,'Compliance Matrix'!$G$4:$G$2256,"C") | D10: =COUNTIFS('Compliance Matrix'!$D$4:$D$2256,$A10,'Compliance Matrix'!$G$4:$G$2256,"PC") | E10: =COUNTIFS('Compliance Matrix'!$D$4:$D$2256,$A10,'Compliance Matrix'!$G$4:$G$2256,"NC") | F10: =COUNTIFS('Compliance Matrix'!$D$4:$D$2256,$A10,'Compliance Matrix'!$G$4:$G$2256,"N/A") | G10: =B10-SUM(C10:F10) | H10: =IF($B10=0,0,C10/$B10) | I10: =SUMIF('Compliance Matrix'!$D$4:$D$2256,$A10,'Compliance Matrix'!$L$4:$L$2256)
A11: 2.2 COMMON OPEARATIONAL PICTURE (COP) | B11: =COUNTIF('Compliance Matrix'!$D$4:$D$2256,$A11) | C11: =COUNTIFS('Compliance Matrix'!$D$4:$D$2256,$A11,'Compliance Matrix'!$G$4:$G$2256,"C") | D11: =COUNTIFS('Compliance Matrix'!$D$4:$D$2256,$A11,'Compliance Matrix'!$G$4:$G$2256,"PC") | E11: =COUNTIFS('Compliance Matrix'!$D$4:$D$2256,$A11,'Compliance Matrix'!$G$4:$G$2256,"NC") | F11: =COUNTIFS('Compliance Matrix'!$D$4:$D$2256,$A11,'Compliance Matrix'!$G$4:$G$2256,"N/A") | G11: =B11-SUM(C11:F11) | H11: =IF($B11=0,0,C11/$B11) | I11: =SUMIF('Compliance Matrix'!$D$4:$D$2256,$A11,'Compliance Matrix'!$L$4:$L$2256)
A12: 2.3 INCIDENT AND RESOURCE MANAGEMENT SYSTEM (IRMS) | B12: =COUNTIF('Compliance Matrix'!$D$4:$D$2256,$A12) | C12: =COUNTIFS('Compliance Matrix'!$D$4:$D$2256,$A12,'Compliance Matrix'!$G$4:$G$2256,"C") | D12: =COUNTIFS('Compliance Matrix'!$D$4:$D$2256,$A12,'Compliance Matrix'!$G$4:$G$2256,"PC") | E12: =COUNTIFS('Compliance Matrix'!$D$4:$D$2256,$A12,'Compliance Matrix'!$G$4:$G$2256,"NC") | F12: =COUNTIFS('Compliance Matrix'!$D$4:$D$2256,$A12,'Compliance Matrix'!$G$4:$G$2256,"N/A") | G12: =B12-SUM(C12:F12) | H12: =IF($B12=0,0,C12/$B12) | I12: =SUMIF('Compliance Matrix'!$D$4:$D$2256,$A12,'Compliance Matrix'!$L$4:$L$2256)
A13: 2.4 INTEGRATION WITH MOI FIELD SYSTEMS / PLATFORMS / APPS | B13: =COUNTIF('Compliance Matrix'!$D$4:$D$2256,$A13) | C13: =COUNTIFS('Compliance Matrix'!$D$4:$D$2256,$A13,'Compliance Matrix'!$G$4:$G$2256,"C") | D13: =COUNTIFS('Compliance Matrix'!$D$4:$D$2256,$A13,'Compliance Matrix'!$G$4:$G$2256,"PC") | E13: =COUNTIFS('Compliance Matrix'!$D$4:$D$2256,$A13,'Compliance Matrix'!$G$4:$G$2256,"NC") | F13: =COUNTIFS('Compliance Matrix'!$D$4:$D$2256,$A13,'Compliance Matrix'!$G$4:$G$2256,"N/A") | G13: =B13-SUM(C13:F13) | H13: =IF($B13=0,0,C13/$B13) | I13: =SUMIF('Compliance Matrix'!$D$4:$D$2256,$A13,'Compliance Matrix'!$L$4:$L$2256)
A14: 2.5 INTEGRATION WITH VIDEO MANAGEMENT SYSTEM (VMS) AND VIDEO ANALYTICS (VA) | B14: =COUNTIF('Compliance Matrix'!$D$4:$D$2256,$A14) | C14: =COUNTIFS('Compliance Matrix'!$D$4:$D$2256,$A14,'Compliance Matrix'!$G$4:$G$2256,"C") | D14: =COUNTIFS('Compliance Matrix'!$D$4:$D$2256,$A14,'Compliance Matrix'!$G$4:$G$2256,"PC") | E14: =COUNTIFS('Compliance Matrix'!$D$4:$D$2256,$A14,'Compliance Matrix'!$G$4:$G$2256,"NC") | F14: =COUNTIFS('Compliance Matrix'!$D$4:$D$2256,$A14,'Compliance Matrix'!$G$4:$G$2256,"N/A") | G14: =B14-SUM(C14:F14) | H14: =IF($B14=0,0,C14/$B14) | I14: =SUMIF('Compliance Matrix'!$D$4:$D$2256,$A14,'Compliance Matrix'!$L$4:$L$2256)
A15: 2.6 IP TELEPHONY (VoIP) | B15: =COUNTIF('Compliance Matrix'!$D$4:$D$2256,$A15) | C15: =COUNTIFS('Compliance Matrix'!$D$4:$D$2256,$A15,'Compliance Matrix'!$G$4:$G$2256,"C") | D15: =COUNTIFS('Compliance Matrix'!$D$4:$D$2256,$A15,'Compliance Matrix'!$G$4:$G$2256,"PC") | E15: =COUNTIFS('Compliance Matrix'!$D$4:$D$2256,$A15,'Compliance Matrix'!$G$4:$G$2256,"NC") | F15: =COUNTIFS('Compliance Matrix'!$D$4:$D$2256,$A15,'Compliance Matrix'!$G$4:$G$2256,"N/A") | G15: =B15-SUM(C15:F15) | H15: =IF($B15=0,0,C15/$B15) | I15: =SUMIF('Compliance Matrix'!$D$4:$D$2256,$A15,'Compliance Matrix'!$L$4:$L$2256)
... A17: 2.8 INTEGRATION WITH EXISTING VIDEO DISPLAY SYSTEMS (VDS) | B17: =COUNTIF('Compliance Matrix'!$D$4:$D$2256,$A17) | C17: =COUNTIFS('Compliance Matrix'!$D$4:$D$2256,$A17,'Compliance Matrix'!$G$4:$G$2256,"C") | D17: =COUNTIFS('Compliance Matrix'!$D$4:$D$2256,$A17,'Compliance Matrix'!$G$4:$G$2256,"PC") | E17: =COUNTIFS('Compliance Matrix'!$D$4:$D$2256,$A17,'Compliance Matrix'!$G$4:$G$2256,"NC") | F17: =COUNTIFS('Compliance Matrix'!$D$4:$D$2256,$A17,'Compliance Matrix'!$G$4:$G$2256,"N/A") | G17: =B17-SUM(C17:F17) | H17: =IF($B17=0,0,C17/$B17) | I17: =SUMIF('Compliance Matrix'!$D$4:$D$2256,$A17,'Compliance Matrix'!$L$4:$L$2256)
A18: TOTAL | B18: =SUM(B4:B17) | C18: =SUM(C4:C17) | D18: =SUM(D4:D17) | E18: =SUM(E4:E17) | F18: =SUM(F4:F17) | G18: =SUM(G4:G17) | H18: =IF($B18=0,0,C18/$B18) | I18: =SUM(I4:I17)
A20: Counts update automatically as the vendor fills column G of the Compliance Matrix.
